#usda 1.0
(
    doc = """
    DR Legs (a.k.a. Dr. Legs)

    A bipedal walking robot with a serial-parallel hybrid leg mechanism that exhibits both passive
    and actuated joints with multiple closed kinematic loops, originally presented by Gim et al. in [1].

    This variant removes all mesh geometries and instead provides box primitives for the pelvis and feet.

    References:
    [1] K. G. Gim, J. Kim, and K. Yamane,
        “Design and fabrication of a bipedal robot using serial-parallel hybrid leg mechanism,”
        IEEE/RSJ International Conference on Intelligent Robots and Systems (IROS), 2018

    Copyright (C) 2025, Disney Enterprises, Inc. All rights reserved.
    """
    defaultPrim = "DR_Legs"
    kilogramsPerUnit = 1
    metersPerUnit = 1
    upAxis = "Z"
)

def Xform "DR_Legs"
{
    def Scope "RigidBodies"
    {
        def Xform "pelvis" (
            prepend apiSchemas = ["PhysicsRigidBodyAPI", "PhysicsMassAPI"]
            customData = {
                string uuid = "b94e9fc1-7daf-4ca6-8ea3-39f618072e50"
            }
        )
        {
            point3f physics:centerOfMass = (0, 0, 0)
            float3 physics:diagonalInertia = (0.0010557076, 0.001077219, 0.0019778116)
            float physics:mass = 0.6031972
            quatf physics:principalAxes = (-0.000026873333, -0.42902488, 0.000012762927, 0.90329266)
            float3 xformOp:rotateXYZ = (0, 0, 0)
            double3 xformOp:translate = (0.002101909618626017, -5.151716380872065e-9, 0.014322280571374113)
            uniform token[] xformOpOrder = ["xformOp:translate", "xformOp:rotateXYZ"]

            def Scope "Geometry"
            {
                def Scope "Primary"
                {
                    def Cube "box_0" (
                        prepend apiSchemas = ["PhysicsCollisionAPI", "PhysicsMeshCollisionAPI", "MaterialBindingAPI"]
                        customData = {
                            string layer = "Primary"
                        }
                    )
                    {
                        color3f[] primvars:displayColor = [(0.2784314, 0.4117647, 1)]
                        float3[] extent = [(-1, -1, -1), (1, 1, 1)]
                        float3 xformOp:scale = (0.0425, 0.12, 0.0275)
                        float3 xformOp:rotateXYZ = (0, 0, 0)
                        double3 xformOp:translate = (7.5e-06, 0.0, -7.5e-06)
                        uniform token[] xformOpOrder = ["xformOp:translate", "xformOp:rotateXYZ", "xformOp:scale"]
                    }
                }
            }
        }

        def Xform "hip_servos_l_i" (
            prepend apiSchemas = ["PhysicsRigidBodyAPI", "PhysicsMassAPI"]
            customData = {
                string uuid = "f3d50162-a95d-4f08-a10d-3626ca60bf1f"
            }
        )
        {
            point3f physics:centerOfMass = (0, 0, 0)
            float3 physics:diagonalInertia = (0.000053400825, 0.00006784994, 0.00008766015)
            float physics:mass = 0.17882477
            quatf physics:principalAxes = (0.48116192, 0.39197016, 0.5899233, -0.5165589)
            float3 xformOp:rotateXYZ = (0, 0, 0)
            double3 xformOp:translate = (0.030665841779290715, 0.04051816319949933, -0.0010819794604215373)
            uniform token[] xformOpOrder = ["xformOp:translate", "xformOp:rotateXYZ"]
        }

        def Xform "hip_servos_l_o" (
            prepend apiSchemas = ["PhysicsRigidBodyAPI", "PhysicsMassAPI"]
            customData = {
                string uuid = "b70bb03a-7c34-4197-9de8-c88d823b6b81"
            }
        )
        {
            point3f physics:centerOfMass = (0, 0, 0)
            float3 physics:diagonalInertia = (0.000056233544, 0.000069777976, 0.00009221932)
            float physics:mass = 0.18211369
            quatf physics:principalAxes = (0.44516498, 0.34058046, 0.61878926, -0.55039346)
            float3 xformOp:rotateXYZ = (0, 0, 0)
            double3 xformOp:translate = (0.020677044864646485, 0.09932240498331744, -0.0013202946573605712)
            uniform token[] xformOpOrder = ["xformOp:translate", "xformOp:rotateXYZ"]
        }

        def Xform "hip_servos_r_i" (
            prepend apiSchemas = ["PhysicsRigidBodyAPI", "PhysicsMassAPI"]
            customData = {
                string uuid = "8b6c729d-ca7a-423d-a53c-3f2dc47039d4"
            }
        )
        {
            point3f physics:centerOfMass = (0, 0, 0)
            float3 physics:diagonalInertia = (0.0000534138, 0.00006788007, 0.00008764792)
            float physics:mass = 0.17880437
            quatf physics:principalAxes = (-0.51644313, 0.5898324, 0.39251828, 0.48095065)
            float3 xformOp:rotateXYZ = (0, 0, 0)
            double3 xformOp:translate = (0.030668512193840657, -0.0405251960980168, -0.0010821918450495613)
            uniform token[] xformOpOrder = ["xformOp:translate", "xformOp:rotateXYZ"]
        }

        def Xform "hip_servos_r_o" (
            prepend apiSchemas = ["PhysicsRigidBodyAPI", "PhysicsMassAPI"]
            customData = {
                string uuid = "86e0ff1e-17ec-4f68-ac30-6a4797cb0bb3"
            }
        )
        {
            point3f physics:centerOfMass = (0, 0, 0)
            float3 physics:diagonalInertia = (0.000056227724, 0.000069761554, 0.00009219729)
            float physics:mass = 0.18209863
            quatf physics:principalAxes = (-0.55023825, 0.6186667, 0.34081557, 0.44534713)
            float3 xformOp:rotateXYZ = (0, 0, 0)
            double3 xformOp:translate = (0.020679489633762087, -0.09932303201219664, -0.0013183760893179931)
            uniform token[] xformOpOrder = ["xformOp:translate", "xformOp:rotateXYZ"]
        }

        def Xform "upperleg_link_l_i" (
            prepend apiSchemas = ["PhysicsRigidBodyAPI", "PhysicsMassAPI"]
            customData = {
                string uuid = "49ef5afd-8a42-46f7-9f11-a87a1612a674"
            }
        )
        {
            point3f physics:centerOfMass = (0, 0, 0)
            float3 physics:diagonalInertia = (0.00002464955, 0.00007145958, 0.000091662114)
            float physics:mass = 0.06993249
            quatf physics:principalAxes = (-0.090332635, 0.6399592, 0.036242392, 0.7622196)
            float3 xformOp:rotateXYZ = (0, 0, 0)
            double3 xformOp:translate = (0.030298670024991467, 0.037592257865829745, -0.07059867890215453)
            uniform token[] xformOpOrder = ["xformOp:translate", "xformOp:rotateXYZ"]
        }

        def Xform "upperleg_link_l_o" (
            prepend apiSchemas = ["PhysicsRigidBodyAPI", "PhysicsMassAPI"]
            customData = {
                string uuid = "8b06e5f0-0bdd-4014-a260-c8aaa4003fce"
            }
        )
        {
            point3f physics:centerOfMass = (0, 0, 0)
            float3 physics:diagonalInertia = (0.000024649655, 0.000071459544, 0.000091662194)
            float physics:mass = 0.06993197
            quatf physics:principalAxes = (-0.04331414, 0.63832134, 0.07564776, 0.76481843)
            float3 xformOp:rotateXYZ = (0, 0, 0)
            double3 xformOp:translate = (0.019691145811145318, 0.10198348911827934, -0.07064605349887665)
            uniform token[] xformOpOrder = ["xformOp:translate", "xformOp:rotateXYZ"]
        }

        def Xform "upperleg_link_r_i" (
            prepend apiSchemas = ["PhysicsRigidBodyAPI", "PhysicsMassAPI"]
            customData = {
                string uuid = "12e08857-e73b-4a9c-916c-81cf1dd6ba93"
            }
        )
        {
            point3f physics:centerOfMass = (0, 0, 0)
            float3 physics:diagonalInertia = (0.000024649673, 0.00007145959, 0.000091662245)
            float physics:mass = 0.06993252
            quatf physics:principalAxes = (-0.63996065, 0.09033177, 0.7622185, 0.03624202)
            float3 xformOp:rotateXYZ = (0, 0, 0)
            double3 xformOp:translate = (0.030298693386572116, -0.03759226567056068, -0.07059864594833895)
            uniform token[] xformOpOrder = ["xformOp:translate", "xformOp:rotateXYZ"]
        }

        def Xform "upperleg_link_r_o" (
            prepend apiSchemas = ["PhysicsRigidBodyAPI", "PhysicsMassAPI"]
            customData = {
                string uuid = "fce8bd12-ed33-4518-a678-57c7d1a1883c"
            }
        )
        {
            point3f physics:centerOfMass = (0, 0, 0)
            float3 physics:diagonalInertia = (0.000024649322, 0.000071459326, 0.00009166168)
            float physics:mass = 0.06993165
            quatf physics:principalAxes = (-0.6383197, 0.043311246, 0.76482004, 0.07564723)
            float3 xformOp:rotateXYZ = (0, 0, 0)
            double3 xformOp:translate = (0.01969109413553567, -0.10198357568380176, -0.07064619490993285)
            uniform token[] xformOpOrder = ["xformOp:translate", "xformOp:rotateXYZ"]
        }

        def Xform "lowerleg_link_l_i" (
            prepend apiSchemas = ["PhysicsRigidBodyAPI", "PhysicsMassAPI"]
            customData = {
                string uuid = "ba62261f-7c64-4b74-86fd-edb7c601c3f9"
            }
        )
        {
            point3f physics:centerOfMass = (0, 0, 0)
            float3 physics:diagonalInertia = (0.000012247744, 0.000094364514, 0.000098323675)
            float physics:mass = 0.08478331
            quatf physics:principalAxes = (0.59322673, -0.58933586, -0.4090903, -0.36525384)
            float3 xformOp:rotateXYZ = (0, 0, 0)
            double3 xformOp:translate = (0.04155519449970874, 0.04011081241819006, -0.1433785138118634)
            uniform token[] xformOpOrder = ["xformOp:translate", "xformOp:rotateXYZ"]
        }

        def Xform "lowerleg_link_l_o" (
            prepend apiSchemas = ["PhysicsRigidBodyAPI", "PhysicsMassAPI"]
            customData = {
                string uuid = "6c435cdd-aef0-485a-942f-6773d13f56f4"
            }
        )
        {
            point3f physics:centerOfMass = (0, 0, 0)
            float3 physics:diagonalInertia = (0.000012248149, 0.000094364776, 0.000098323384)
            float physics:mass = 0.0847833
            quatf physics:principalAxes = (0.6523277, -0.52159506, -0.4614398, -0.29913288)
            float3 xformOp:rotateXYZ = (0, 0, 0)
            double3 xformOp:translate = (0.030797302132512566, 0.10340845553012881, -0.14347877732704237)
            uniform token[] xformOpOrder = ["xformOp:translate", "xformOp:rotateXYZ"]
        }

        def Xform "lowerleg_link_r_i" (
            prepend apiSchemas = ["PhysicsRigidBodyAPI", "PhysicsMassAPI"]
            customData = {
                string uuid = "25cb9d12-8781-4792-be54-82d268167a79"
            }
        )
        {
            point3f physics:centerOfMass = (0, 0, 0)
            float3 physics:diagonalInertia = (0.000012248154, 0.00009436478, 0.00009832339)
            float physics:mass = 0.08478333
            quatf physics:principalAxes = (-0.5894339, 0.5931248, 0.36532176, 0.40903622)
            float3 xformOp:rotateXYZ = (0, 0, 0)
            double3 xformOp:translate = (0.04155531708063938, -0.040110492869283, -0.1433784703206533)
            uniform token[] xformOpOrder = ["xformOp:translate", "xformOp:rotateXYZ"]
        }

        def Xform "lowerleg_link_r_o" (
            prepend apiSchemas = ["PhysicsRigidBodyAPI", "PhysicsMassAPI"]
            customData = {
                string uuid = "314a7cab-22cd-4f9f-870c-884f8af3aaeb"
            }
        )
        {
            point3f physics:centerOfMass = (0, 0, 0)
            float3 physics:diagonalInertia = (0.000012247671, 0.00009436343, 0.000098322525)
            float physics:mass = 0.08478301
            quatf physics:principalAxes = (-0.5217073, 0.6522394, 0.29920465, 0.46139124)
            float3 xformOp:rotateXYZ = (0, 0, 0)
            double3 xformOp:translate = (0.03079717123973264, -0.10340807400211947, -0.14347899908440448)
            uniform token[] xformOpOrder = ["xformOp:translate", "xformOp:rotateXYZ"]
        }

        def Xform "ankle_bracket_a_l_i" (
            prepend apiSchemas = ["PhysicsRigidBodyAPI", "PhysicsMassAPI"]
            customData = {
                string uuid = "dd8d49a3-243f-4e21-8125-7e1deaa485ce"
            }
        )
        {
            point3f physics:centerOfMass = (0, 0, 0)
            float3 physics:diagonalInertia = (0.0000026868045, 0.000005670951, 0.0000058947344)
            float physics:mass = 0.024649119
            quatf physics:principalAxes = (-0.14950699, -0.6345848, 0.019778889, 0.75799644)
            float3 xformOp:rotateXYZ = (0, 0, 0)
            double3 xformOp:translate = (0.025251158338951245, 0.03454304496116212, -0.20544639544649052)
            uniform token[] xformOpOrder = ["xformOp:translate", "xformOp:rotateXYZ"]
        }

        def Xform "ankle_bracket_a_l_o" (
            prepend apiSchemas = ["PhysicsRigidBodyAPI", "PhysicsMassAPI"]
            customData = {
                string uuid = "2d88e8b0-9515-4e34-883b-15c476ead6ce"
            }
        )
        {
            point3f physics:centerOfMass = (0, 0, 0)
            float3 physics:diagonalInertia = (0.0000026868042, 0.000005670952, 0.000005894738)
            float physics:mass = 0.024649126
            quatf physics:principalAxes = (0.632069, 0.022291547, 0.76470226, 0.12337863)
            float3 xformOp:rotateXYZ = (0, 0, 0)
            double3 xformOp:translate = (0.012768078285870538, 0.10292198748097234, -0.20536864386112175)
            uniform token[] xformOpOrder = ["xformOp:translate", "xformOp:rotateXYZ"]
        }

        def Xform "ankle_bracket_a_r_i" (
            prepend apiSchemas = ["PhysicsRigidBodyAPI", "PhysicsMassAPI"]
            customData = {
                string uuid = "3dd8c33b-e577-48b1-b224-6ec62d1b98f6"
            }
        )
        {
            point3f physics:centerOfMass = (0, 0, 0)
            float3 physics:diagonalInertia = (0.000002686805, 0.0000056709537, 0.0000058947403)
            float physics:mass = 0.024649138
            quatf physics:principalAxes = (0.64560926, 0.15446438, 0.7477903, 0.011796402)
            float3 xformOp:rotateXYZ = (0, 0, 0)
            double3 xformOp:translate = (0.024721383277806694, -0.03444963440759924, -0.2053479521986785)
            uniform token[] xformOpOrder = ["xformOp:translate", "xformOp:rotateXYZ"]
        }

        def Xform "ankle_bracket_a_r_o" (
            prepend apiSchemas = ["PhysicsRigidBodyAPI", "PhysicsMassAPI"]
            customData = {
                string uuid = "391e9452-9806-4517-8b39-82229eb6a64f"
            }
        )
        {
            point3f physics:centerOfMass = (0, 0, 0)
            float3 physics:diagonalInertia = (0.000002686804, 0.00000567095, 0.0000058947344)
            float physics:mass = 0.024649117
            quatf physics:principalAxes = (-0.01565519, -0.61980283, 0.1293365, 0.7738678)
            float3 xformOp:rotateXYZ = (0, 0, 0)
            double3 xformOp:translate = (0.013297412197502478, -0.10301532601659746, -0.20546950240647596)
            uniform token[] xformOpOrder = ["xformOp:translate", "xformOp:rotateXYZ"]
        }

        def Xform "ankle_bracket_b_l_i" (
            prepend apiSchemas = ["PhysicsRigidBodyAPI", "PhysicsMassAPI"]
            customData = {
                string uuid = "e371a9bf-7a61-4e20-ab92-829c35b40f11"
            }
        )
        {
            point3f physics:centerOfMass = (0, 0, 0)
            float3 physics:diagonalInertia = (2.1667877e-7, 2.5417216e-7, 2.7437972e-7)
            float physics:mass = 0.006058801
            quatf physics:principalAxes = (0.76291037, -0.06922168, 0.05808454, -0.64015806)
            float3 xformOp:rotateXYZ = (0, 0, 0)
            double3 xformOp:translate = (0.01866989866347636, 0.04262864199443674, -0.23167508669722975)
            uniform token[] xformOpOrder = ["xformOp:translate", "xformOp:rotateXYZ"]
        }

        def Xform "ankle_bracket_b_l_o" (
            prepend apiSchemas = ["PhysicsRigidBodyAPI", "PhysicsMassAPI"]
            customData = {
                string uuid = "abe6791c-a1c0-47e3-9071-7bc7aea80695"
            }
        )
        {
            point3f physics:centerOfMass = (0, 0, 0)
            float3 physics:diagonalInertia = (2.166787e-7, 2.541721e-7, 2.743797e-7)
            float physics:mass = 0.006058798
            quatf physics:principalAxes = (0.7627528, -0.07093922, 0.059525553, -0.64002544)
            float3 xformOp:rotateXYZ = (0, 0, 0)
            double3 xformOp:translate = (0.009762332281919216, 0.09314594630109431, -0.23167509897578695)
            uniform token[] xformOpOrder = ["xformOp:translate", "xformOp:rotateXYZ"]
        }

        def Xform "ankle_bracket_b_r_i" (
            prepend apiSchemas = ["PhysicsRigidBodyAPI", "PhysicsMassAPI"]
            customData = {
                string uuid = "3a527421-833f-4a05-9679-9df029e6f3be"
            }
        )
        {
            point3f physics:centerOfMass = (0, 0, 0)
            float3 physics:diagonalInertia = (2.166787e-7, 2.541721e-7, 2.743797e-7)
            float physics:mass = 0.006058798
            quatf physics:principalAxes = (-0.06922332, 0.76291037, 0.64015776, -0.058085747)
            float3 xformOp:rotateXYZ = (0, 0, 0)
            double3 xformOp:translate = (0.01866989639494399, -0.042628641027285974, -0.23167508851887844)
            uniform token[] xformOpOrder = ["xformOp:translate", "xformOp:rotateXYZ"]
        }

        def Xform "ankle_bracket_b_r_o" (
            prepend apiSchemas = ["PhysicsRigidBodyAPI", "PhysicsMassAPI"]
            customData = {
                string uuid = "f8e405bd-e950-42bb-8145-b4aac497c796"
            }
        )
        {
            point3f physics:centerOfMass = (0, 0, 0)
            float3 physics:diagonalInertia = (2.166787e-7, 2.5417214e-7, 2.743797e-7)
            float physics:mass = 0.006058798
            quatf physics:principalAxes = (-0.07093822, 0.76275295, 0.6400255, -0.059523787)
            float3 xformOp:rotateXYZ = (0, 0, 0)
            double3 xformOp:translate = (0.0097623341871033, -0.09314594666505657, -0.23167508883188814)
            uniform token[] xformOpOrder = ["xformOp:translate", "xformOp:rotateXYZ"]
        }

        def Xform "foot_l" (
            prepend apiSchemas = ["PhysicsRigidBodyAPI", "PhysicsMassAPI"]
            customData = {
                string uuid = "a8d7ce27-5aae-4fc4-b780-d30d3664ebb8"
            }
        )
        {
            point3f physics:centerOfMass = (0, 0, 0)
            float3 physics:diagonalInertia = (0.00006685645, 0.0001222389, 0.00013535675)
            float physics:mass = 0.14403841
            quatf physics:principalAxes = (0.9960831, -0.017946612, -0.008696691, 0.08614412)
            float3 xformOp:rotateXYZ = (0, 0, 0)
            double3 xformOp:translate = (0.022351283592025584, 0.068982063136453, -0.245734731249804)
            uniform token[] xformOpOrder = ["xformOp:translate", "xformOp:rotateXYZ"]

            def Scope "Geometry"
            {
                def Scope "Primary"
                {
                    def Cube "box_0" (
                        prepend apiSchemas = ["PhysicsCollisionAPI", "PhysicsMeshCollisionAPI", "MaterialBindingAPI"]
                        customData = {
                            string layer = "Primary"
                        }
                    )
                    {
                        color3f[] primvars:displayColor = [(0.1, 0.1, 0.1)]
                        float3[] extent = [(-1, -1, -1), (1, 1, 1)]
                        float3 xformOp:scale = (0.0585, 0.035, 0.0015)
                        float3 xformOp:rotateXYZ = (0, 0, 10)
                        double3 xformOp:translate = (-0.003703450760000001, -0.00031338953000001335, -0.016440363749999964)
                        uniform token[] xformOpOrder = ["xformOp:translate", "xformOp:rotateXYZ", "xformOp:scale"]
                    }
                }
            }
        }

        def Xform "foot_r" (
            prepend apiSchemas = ["PhysicsRigidBodyAPI", "PhysicsMassAPI"]
            customData = {
                string uuid = "86f5a3a3-7959-43c9-b231-33eaad9278af"
            }
        )
        {
            point3f physics:centerOfMass = (0, 0, 0)
            float3 physics:diagonalInertia = (0.00006685645, 0.00012223887, 0.00013535678)
            float physics:mass = 0.14403841
            quatf physics:principalAxes = (0.99608326, 0.017956372, -0.008697486, -0.08613999)
            float3 xformOp:rotateXYZ = (0, 0, 0)
            double3 xformOp:translate = (0.022351258779097896, -0.06898219772744969, -0.24573473417337738)
            uniform token[] xformOpOrder = ["xformOp:translate", "xformOp:rotateXYZ"]

            def Scope "Geometry"
            {
                def Scope "Primary"
                {
                    def Cube "box_0" (
                        prepend apiSchemas = ["PhysicsCollisionAPI", "PhysicsMeshCollisionAPI", "MaterialBindingAPI"]
                        customData = {
                            string layer = "Primary"
                        }
                    )
                    {
                        color3f[] primvars:displayColor = [(0.1, 0.1, 0.1)]
                        float3[] extent = [(-1, -1, -1), (1, 1, 1)]
                        float3 xformOp:scale = (0.0585, 0.035, 0.0015)
                        float3 xformOp:rotateXYZ = (0, 0, -10)
                        double3 xformOp:translate = (-0.003703450760000001, 0.00031338953000001335, -0.016440363749999964)
                        uniform token[] xformOpOrder = ["xformOp:translate", "xformOp:rotateXYZ", "xformOp:scale"]
                    }
                }
            }
        }

        def Xform "servohorn_l_i" (
            prepend apiSchemas = ["PhysicsRigidBodyAPI", "PhysicsMassAPI"]
            customData = {
                string uuid = "21648279-f424-46bf-8e41-9c8da7e9f9ff"
            }
        )
        {
            point3f physics:centerOfMass = (0, 0, 0)
            float3 physics:diagonalInertia = (4.5969298e-7, 0.00000470973, 0.000004753943)
            float physics:mass = 0.012728027
            quatf physics:principalAxes = (0.6814827, 0.69268906, -0.04732246, 0.23135215)
            float3 xformOp:rotateXYZ = (0, 0, 0)
            double3 xformOp:translate = (0.0711804338017446, 0.026708016169720003, 0.024556580097565898)
            uniform token[] xformOpOrder = ["xformOp:translate", "xformOp:rotateXYZ"]
        }

        def Xform "servohorn_l_o" (
            prepend apiSchemas = ["PhysicsRigidBodyAPI", "PhysicsMassAPI"]
            customData = {
                string uuid = "20a8feb5-185c-459f-b9ca-5514fa4fc6f9"
            }
        )
        {
            point3f physics:centerOfMass = (0, 0, 0)
            float3 physics:diagonalInertia = (4.5969358e-7, 0.0000047097365, 0.0000047539493)
            float physics:mass = 0.012728056
            quatf physics:principalAxes = (0.675075, 0.7111422, -0.10719832, 0.16449639)
            float3 xformOp:rotateXYZ = (0, 0, 0)
            double3 xformOp:translate = (0.054716054807684614, 0.12625215526713546, 0.02438464146270033)
            uniform token[] xformOpOrder = ["xformOp:translate", "xformOp:rotateXYZ"]
        }

        def Xform "servohorn_r_i" (
            prepend apiSchemas = ["PhysicsRigidBodyAPI", "PhysicsMassAPI"]
            customData = {
                string uuid = "396d463c-1eae-42a6-aa2a-1e779a446ae1"
            }
        )
        {
            point3f physics:centerOfMass = (0, 0, 0)
            float3 physics:diagonalInertia = (4.596935e-7, 0.0000047097324, 0.000004753945)
            float physics:mass = 0.012728046
            quatf physics:principalAxes = (-0.6811434, 0.69300437, 0.04726037, 0.23141952)
            float3 xformOp:rotateXYZ = (0, 0, 0)
            double3 xformOp:translate = (0.07118029087409224, -0.026707982771408813, 0.024556937542896982)
            uniform token[] xformOpOrder = ["xformOp:translate", "xformOp:rotateXYZ"]
        }

        def Xform "servohorn_r_o" (
            prepend apiSchemas = ["PhysicsRigidBodyAPI", "PhysicsMassAPI"]
            customData = {
                string uuid = "8517edda-bfa2-4272-9056-397d97a0e2bb"
            }
        )
        {
            point3f physics:centerOfMass = (0, 0, 0)
            float3 physics:diagonalInertia = (4.596915e-7, 0.0000047096114, 0.000004753824)
            float physics:mass = 0.012727745
            quatf physics:principalAxes = (-0.6747533, 0.711465, 0.10707438, 0.16450103)
            float3 xformOp:rotateXYZ = (0, 0, 0)
            double3 xformOp:translate = (0.054715770978549114, -0.12625212168015337, 0.024384094611794152)
            uniform token[] xformOpOrder = ["xformOp:translate", "xformOp:rotateXYZ"]
        }

        def Xform "upperleg_rod_l_i" (
            prepend apiSchemas = ["PhysicsRigidBodyAPI", "PhysicsMassAPI"]
            customData = {
                string uuid = "0b67781e-d201-4620-b89f-73bf159858c6"
            }
        )
        {
            point3f physics:centerOfMass = (0, 0, 0)
            float3 physics:diagonalInertia = (2.7881356e-7, 0.000024395013, 0.000024495523)
            float physics:mass = 0.016274415
            quatf physics:principalAxes = (0.5296609, 0.44026607, 0.5533225, -0.46846488)
            float3 xformOp:rotateXYZ = (0, 0, 0)
            double3 xformOp:translate = (0.08516391588766184, 0.03648027351475806, -0.030824305324425073)
            uniform token[] xformOpOrder = ["xformOp:translate", "xformOp:rotateXYZ"]
        }

        def Xform "upperleg_rod_l_o" (
            prepend apiSchemas = ["PhysicsRigidBodyAPI", "PhysicsMassAPI"]
            customData = {
                string uuid = "e87c54a9-ef94-4239-89fb-6b8a50e3620e"
            }
        )
        {
            point3f physics:centerOfMass = (0, 0, 0)
            float3 physics:diagonalInertia = (2.7881356e-7, 0.000024395013, 0.000024495523)
            float physics:mass = 0.016274415
            quatf physics:principalAxes = (0.52871954, 0.4391546, 0.55420506, -0.46952704)
            float3 xformOp:rotateXYZ = (0, 0, 0)
            double3 xformOp:translate = (0.07100238225105991, 0.12181761497453182, -0.031114401944382274)
            uniform token[] xformOpOrder = ["xformOp:translate", "xformOp:rotateXYZ"]
        }

        def Xform "upperleg_rod_r_i" (
            prepend apiSchemas = ["PhysicsRigidBodyAPI", "PhysicsMassAPI"]
            customData = {
                string uuid = "266f0f84-ef9c-454a-9334-c06a5f3eb2bb"
            }
        )
        {
            point3f physics:centerOfMass = (0, 0, 0)
            float3 physics:diagonalInertia = (2.7881356e-7, 0.000024395013, 0.000024495523)
            float physics:mass = 0.016274415
            quatf physics:principalAxes = (-0.44026607, -0.5296609, -0.46846488, 0.5533225)
            float3 xformOp:rotateXYZ = (0, 0, 0)
            double3 xformOp:translate = (0.08516397375038028, -0.036479945358977896, -0.030824305324425382)
            uniform token[] xformOpOrder = ["xformOp:translate", "xformOp:rotateXYZ"]
        }

        def Xform "upperleg_rod_r_o" (
            prepend apiSchemas = ["PhysicsRigidBodyAPI", "PhysicsMassAPI"]
            customData = {
                string uuid = "4135d3d9-6213-45f4-9d75-ef354a078806"
            }
        )
        {
            point3f physics:centerOfMass = (0, 0, 0)
            float3 physics:diagonalInertia = (2.7881356e-7, 0.000024395013, 0.000024495523)
            float physics:mass = 0.016274415
            quatf physics:principalAxes = (-0.4391546, -0.52871954, -0.46952704, 0.55420506)
            float3 xformOp:rotateXYZ = (0, 0, 0)
            double3 xformOp:translate = (0.07100244011377821, -0.12181728681875158, -0.031114401944382256)
            uniform token[] xformOpOrder = ["xformOp:translate", "xformOp:rotateXYZ"]
        }
    }

    def Scope "Joints"
    {
        def PhysicsRevoluteJoint "j1_l_i" (
            prepend apiSchemas = ["PhysicsDriveAPI:angular"]
            customData = {
                string uuid = "84de66df-b1fd-4e7e-af23-0a6ae1aeeab4"
            }
        )
        {
            float drive:angular:physics:maxForce = inf
            uniform token physics:axis = "X"
            rel physics:body0 = </DR_Legs/RigidBodies/pelvis>
            rel physics:body1 = </DR_Legs/RigidBodies/hip_servos_l_i>
            point3f physics:localPos0 = (0.0010024428, 0.0336882, -0.02857228)
            point3f physics:localPos1 = (-0.02756149, -0.0068299677, -0.01316802)
            quatf physics:localRot0 = (0.70441604, 0.70441604, 0.061628416, 0.061628416)
            quatf physics:localRot1 = (0.70441604, 0.70441604, 0.061628416, 0.061628416)
            float physics:lowerLimit = -inf
            float physics:upperLimit = inf
        }

        def PhysicsRevoluteJoint "j2_l_i" (
            prepend apiSchemas = ["PhysicsDriveAPI:angular"]
            customData = {
                string uuid = "fb96b340-13af-4e52-9a6b-eb733f0d17bb"
            }
        )
        {
            float drive:angular:physics:maxForce = inf
            uniform token physics:axis = "X"
            rel physics:body0 = </DR_Legs/RigidBodies/hip_servos_l_i>
            rel physics:body1 = </DR_Legs/RigidBodies/upperleg_link_l_i>
            point3f physics:localPos0 = (-0.007708361, -0.020083865, -0.01316802)
            point3f physics:localPos1 = (-0.007341189, -0.017157959, 0.056348678)
            quatf physics:localRot0 = (0.7629704, 0.068558566, -0.05752747, -0.6402082)
            quatf physics:localRot1 = (0.7629704, 0.068558566, -0.05752747, -0.6402082)
            float physics:lowerLimit = -inf
            float physics:upperLimit = inf
        }

        def PhysicsRevoluteJoint "j3_l_i" (
            customData = {
                string uuid = "5d132508-b322-4f40-9a32-40e1f284876e"
            }
        )
        {
            uniform token physics:axis = "X"
            rel physics:body0 = </DR_Legs/RigidBodies/upperleg_link_l_i>
            rel physics:body1 = </DR_Legs/RigidBodies/lowerleg_link_l_i>
            point3f physics:localPos0 = (0.009105989, 0.002496661, -0.05188919)
            point3f physics:localPos1 = (-0.0021505358, -0.00002189371, 0.020890646)
            quatf physics:localRot0 = (-0.058084864, 0.6401578, 0.7629104, -0.069222845)
            quatf physics:localRot1 = (-0.058084864, 0.6401578, 0.7629104, -0.069222845)
        }

        def PhysicsRevoluteJoint "j4_l_i" (
            customData = {
                string uuid = "d12514dc-b7c1-4006-96f6-8edadaaccdad"
            }
        )
        {
            uniform token physics:axis = "X"
            rel physics:body0 = </DR_Legs/RigidBodies/lowerleg_link_l_i>
            rel physics:body1 = </DR_Legs/RigidBodies/ankle_bracket_a_l_i>
            point3f physics:localPos0 = (-0.016862633, -0.0026160334, -0.060753856)
            point3f physics:localPos1 = (-0.00055859715, 0.002951734, 0.0013140251)
            quatf physics:localRot0 = (0.5805313, -0.5016079, -0.49838692, -0.403712)
            quatf physics:localRot1 = (0.5805313, -0.5016079, -0.49838692, -0.403712)
        }

        def PhysicsRevoluteJoint "j5_l_i" (
            customData = {
                string uuid = "67626dab-b4fc-4a55-aaba-196831fac82e"
            }
        )
        {
            uniform token physics:axis = "X"
            rel physics:body0 = </DR_Legs/RigidBodies/ankle_bracket_a_l_i>
            rel physics:body1 = </DR_Legs/RigidBodies/ankle_bracket_b_l_i>
            point3f physics:localPos0 = (-0.005521714, 0.0020766025, -0.026228698)
            point3f physics:localPos1 = (0.0010595453, -0.0060089943, -7.050231e-9)
            quatf physics:localRot0 = (0.70710313, 0.6959651, 0.12503013, -0.002277571)
            quatf physics:localRot1 = (0.70710313, 0.6959651, 0.12503013, -0.002277571)
        }

        def PhysicsRevoluteJoint "j6_l_i" (
            prepend apiSchemas = ["PhysicsDriveAPI:angular"]
            customData = {
                string uuid = "f7ff8cae-a6c6-4e48-be27-906929a2c2cb"
            }
        )
        {
            float drive:angular:physics:maxForce = inf
            uniform token physics:axis = "X"
            rel physics:body0 = </DR_Legs/RigidBodies/foot_l>
            rel physics:body1 = </DR_Legs/RigidBodies/ankle_bracket_b_l_i>
            point3f physics:localPos0 = (-0.0026218395, -0.032362416, 0.014059638)
            point3f physics:localPos1 = (0.0010595453, -0.0060089943, -7.050231e-9)
            quatf physics:localRot0 = (0.7629104, -0.069222845, 0.058084864, -0.6401578)
            quatf physics:localRot1 = (0.7629104, -0.069222845, 0.058084864, -0.6401578)
            float physics:lowerLimit = -inf
            float physics:upperLimit = inf
        }

        def PhysicsRevoluteJoint "j7_l_i" (
            prepend apiSchemas = ["PhysicsDriveAPI:angular"]
            customData = {
                string uuid = "b582de85-d2a8-46ea-aef8-b3e0d73950d8"
            }
        )
        {
            float drive:angular:physics:maxForce = inf
            uniform token physics:axis = "X"
            rel physics:body0 = </DR_Legs/RigidBodies/hip_servos_l_i>
            rel physics:body1 = </DR_Legs/RigidBodies/servohorn_l_i>
            point3f physics:localPos0 = (0.015927026, -0.015916308, 0.01533198)
            point3f physics:localPos1 = (-0.024587566, -0.0021061616, -0.01030658)
            quatf physics:localRot0 = (0.6595576, -0.38962528, 0.32693443, -0.55343455)
            quatf physics:localRot1 = (0.6595576, -0.38962528, 0.32693443, -0.55343455)
            float physics:lowerLimit = -inf
            float physics:upperLimit = inf
        }

        def PhysicsRevoluteJoint "j8_l_i" (
            customData = {
                string uuid = "abda9a58-b449-40a1-829f-a6f8b59c5344"
            }
        )
        {
            uniform token physics:axis = "X"
            rel physics:body0 = </DR_Legs/RigidBodies/servohorn_l_i>
            rel physics:body1 = </DR_Legs/RigidBodies/upperleg_rod_l_i>
            point3f physics:localPos0 = (0.017216353, 0.0104182875, 0.0078682965)
            point3f physics:localPos1 = (0.0032328705, 0.0006460301, 0.063249186)
            quatf physics:localRot0 = (-0.016730923, 0.64256984, 0.7657849, -0.019939138)
            quatf physics:localRot1 = (-0.016730923, 0.64256984, 0.7657849, -0.019939138)
        }

        def PhysicsRevoluteJoint "j9_l_i" (
            customData = {
                string uuid = "1483eec4-5be4-4fd1-8183-956679920199"
            }
        )
        {
            uniform token physics:axis = "X"
            rel physics:body0 = </DR_Legs/RigidBodies/upperleg_rod_l_i>
            rel physics:body1 = </DR_Legs/RigidBodies/lowerleg_link_l_i>
            point3f physics:localPos0 = (-0.0032588597, -0.0004986371, -0.063249186)
            point3f physics:localPos1 = (0.04034986, -0.004129176, 0.049305025)
            quatf physics:localRot0 = (0.7657849, -0.019939138, 0.016730923, -0.64256984)
            quatf physics:localRot1 = (0.7657849, -0.019939138, 0.016730923, -0.64256984)
        }

        def PhysicsRevoluteJoint "j1_l_o" (
            customData = {
                string uuid = "7c8a2159-225a-4f31-be18-5f437e243c52"
            }
        )
        {
            uniform token physics:axis = "X"
            rel physics:body0 = </DR_Legs/RigidBodies/pelvis>
            rel physics:body1 = </DR_Legs/RigidBodies/hip_servos_l_o>
            point3f physics:localPos0 = (-0.0036229661, 0.09735221, -0.02857228)
            point3f physics:localPos1 = (-0.022198102, -0.0019702043, -0.012929705)
            quatf physics:localRot0 = (0.70441604, 0.70441604, 0.061628416, 0.061628416)
            quatf physics:localRot1 = (0.70441604, 0.70441604, 0.061628416, 0.061628416)
        }

        def PhysicsRevoluteJoint "j2_l_o" (
            prepend apiSchemas = ["PhysicsDriveAPI:angular"]
            customData = {
                string uuid = "9a780419-f2f2-4103-8f48-9e6b1dd59bc1"
            }
        )
        {
            float drive:angular:physics:maxForce = inf
            uniform token physics:axis = "X"
            rel physics:body0 = </DR_Legs/RigidBodies/hip_servos_l_o>
            rel physics:body1 = </DR_Legs/RigidBodies/upperleg_link_l_o>
            point3f physics:localPos0 = (-0.013491806, 0.01631949, -0.012929705)
            point3f physics:localPos1 = (-0.012505907, 0.013658405, 0.056396052)
            quatf physics:localRot0 = (0.056022633, 0.6403416, 0.7631294, 0.066765174)
            quatf physics:localRot1 = (0.056022633, 0.6403416, 0.7631294, 0.066765174)
            float physics:lowerLimit = -inf
            float physics:upperLimit = inf
        }

        def PhysicsRevoluteJoint "j3_l_o" (
            customData = {
                string uuid = "180c5b7c-d66c-468c-8aa9-4a4f8350434b"
            }
        )
        {
            uniform token physics:axis = "X"
            rel physics:body0 = </DR_Legs/RigidBodies/upperleg_link_l_o>
            rel physics:body1 = </DR_Legs/RigidBodies/lowerleg_link_l_o>
            point3f physics:localPos0 = (0.009170396, 0.0007259836, -0.0519328)
            point3f physics:localPos1 = (-0.0019357597, -0.0006989828, 0.020899925)
            quatf physics:localRot0 = (-0.05952467, 0.64002556, 0.7627528, -0.07093874)
            quatf physics:localRot1 = (-0.05952467, 0.64002556, 0.7627528, -0.07093874)
        }

        def PhysicsRevoluteJoint "j4_l_o" (
            customData = {
                string uuid = "54815d15-5973-485f-950c-fcb79e9c10cf"
            }
        )
        {
            uniform token physics:axis = "X"
            rel physics:body0 = </DR_Legs/RigidBodies/lowerleg_link_l_o>
            rel physics:body1 = </DR_Legs/RigidBodies/ankle_bracket_a_l_o>
            point3f physics:localPos0 = (-0.017009426, -0.0033568768, -0.060676545)
            point3f physics:localPos1 = (0.0010197985, -0.0028704088, 0.0012133226)
            quatf physics:localRot0 = (0.58143795, -0.5027277, -0.49725735, -0.40240514)
            quatf physics:localRot1 = (0.58143795, -0.5027277, -0.49725735, -0.40240514)
        }

        def PhysicsRevoluteJoint "j5_l_o" (
            customData = {
                string uuid = "a3fb5dff-f57c-4e46-a23f-a7d5d53f9dd0"
            }
        )
        {
            uniform token physics:axis = "X"
            rel physics:body0 = </DR_Legs/RigidBodies/ankle_bracket_a_l_o>
            rel physics:body1 = </DR_Legs/RigidBodies/ankle_bracket_b_l_o>
            point3f physics:localPos0 = (-0.0040652934, -0.0037670475, -0.02630645)
            point3f physics:localPos1 = (-0.0010595475, 0.0060089934, 5.228326e-9)
            quatf physics:localRot0 = (-0.6956821, 0.7070962, -0.003868105, -0.1265953)
            quatf physics:localRot1 = (-0.6956821, 0.7070962, -0.003868105, -0.1265953)
        }

        def PhysicsRevoluteJoint "j6_l_o" (
            customData = {
                string uuid = "93d5670d-4514-4c44-a0b7-8be8380c3c57"
            }
        )
        {
            uniform token physics:axis = "X"
            rel physics:body0 = </DR_Legs/RigidBodies/ankle_bracket_b_l_o>
            rel physics:body1 = </DR_Legs/RigidBodies/foot_l>
            point3f physics:localPos0 = (-0.0010595475, 0.0060089934, 5.228326e-9)
            point3f physics:localPos1 = (-0.013648499, 0.030172877, 0.014059638)
            quatf physics:localRot0 = (-0.05952467, 0.64002556, 0.7627528, -0.07093874)
            quatf physics:localRot1 = (-0.05952467, 0.64002556, 0.7627528, -0.07093874)
        }

        def PhysicsRevoluteJoint "j7_l_o" (
            prepend apiSchemas = ["PhysicsDriveAPI:angular"]
            customData = {
                string uuid = "06b79073-2be7-4774-84e6-42caa478be39"
            }
        )
        {
            float drive:angular:physics:maxForce = inf
            uniform token physics:axis = "X"
            rel physics:body0 = </DR_Legs/RigidBodies/hip_servos_l_o>
            rel physics:body1 = </DR_Legs/RigidBodies/servohorn_l_o>
            point3f physics:localPos0 = (0.010143581, 0.020487046, 0.015570295)
            point3f physics:localPos1 = (-0.02389543, -0.0064427042, -0.010134641)
            quatf physics:localRot0 = (-0.32886937, 0.5522869, 0.65818995, -0.39193124)
            quatf physics:localRot1 = (-0.32886937, 0.5522869, 0.65818995, -0.39193124)
            float physics:lowerLimit = -inf
            float physics:upperLimit = inf
        }

        def PhysicsRevoluteJoint "j8_l_o" (
            customData = {
                string uuid = "ddca2297-c60f-4405-a99a-d670e5982e88"
            }
        )
        {
            uniform token physics:axis = "X"
            rel physics:body0 = </DR_Legs/RigidBodies/servohorn_l_o>
            rel physics:body1 = </DR_Legs/RigidBodies/upperleg_rod_l_o>
            point3f physics:localPos0 = (0.019769212, -0.003744426, 0.0077363984)
            point3f physics:localPos1 = (0.0034828843, 0.0006901143, 0.06323544)
            quatf physics:localRot0 = (-0.018020606, 0.642535, 0.7657433, -0.021476122)
            quatf physics:localRot1 = (-0.018020606, 0.642535, 0.7657433, -0.021476122)
        }

        def PhysicsRevoluteJoint "j9_l_o" (
            customData = {
                string uuid = "55e60c34-c360-4543-b350-9841b341114c"
            }
        )
        {
            uniform token physics:axis = "X"
            rel physics:body0 = </DR_Legs/RigidBodies/upperleg_rod_l_o>
            rel physics:body1 = </DR_Legs/RigidBodies/lowerleg_link_l_o>
            point3f physics:localPos0 = (-0.0035088737, -0.0005427213, -0.06323544)
            point3f physics:localPos1 = (0.036696207, 0.017866438, 0.049128935)
            quatf physics:localRot0 = (0.7657433, -0.021476122, 0.018020606, -0.642535)
            quatf physics:localRot1 = (0.7657433, -0.021476122, 0.018020606, -0.642535)
        }

        def PhysicsRevoluteJoint "j1_r_i" (
            prepend apiSchemas = ["PhysicsDriveAPI:angular"]
            customData = {
                string uuid = "f212f8ec-bf97-42ca-b10a-99b78646fc72"
            }
        )
        {
            float drive:angular:physics:maxForce = inf
            uniform token physics:axis = "X"
            rel physics:body0 = </DR_Legs/RigidBodies/pelvis>
            rel physics:body1 = </DR_Legs/RigidBodies/hip_servos_r_i>
            point3f physics:localPos0 = (0.0010024428, -0.03368819, -0.02857228)
            point3f physics:localPos1 = (-0.02756416, 0.0068370006, -0.013167808)
            quatf physics:localRot0 = (0.70441604, 0.70441604, -0.061628416, -0.061628416)
            quatf physics:localRot1 = (0.70441604, 0.70441604, -0.061628416, -0.061628416)
            float physics:lowerLimit = -inf
            float physics:upperLimit = inf
        }

        def PhysicsRevoluteJoint "j2_r_i" (
            prepend apiSchemas = ["PhysicsDriveAPI:angular"]
            customData = {
                string uuid = "1311ae4a-c3b2-49d6-bb1e-0758856cb666"
            }
        )
        {
            float drive:angular:physics:maxForce = inf
            uniform token physics:axis = "X"
            rel physics:body0 = </DR_Legs/RigidBodies/hip_servos_r_i>
            rel physics:body1 = </DR_Legs/RigidBodies/upperleg_link_r_i>
            point3f physics:localPos0 = (-0.007711031, 0.020090898, -0.013167808)
            point3f physics:localPos1 = (-0.007341212, 0.017157968, 0.056348644)
            quatf physics:localRot0 = (0.068558566, 0.7629704, 0.6402082, 0.05752747)
            quatf physics:localRot1 = (0.068558566, 0.7629704, 0.6402082, 0.05752747)
            float physics:lowerLimit = -inf
            float physics:upperLimit = inf
        }

        def PhysicsRevoluteJoint "j3_r_i" (
            customData = {
                string uuid = "967a154b-8fd5-4362-8f63-670adb7ed1b8"
            }
        )
        {
            uniform token physics:axis = "X"
            rel physics:body0 = </DR_Legs/RigidBodies/upperleg_link_r_i>
            rel physics:body1 = </DR_Legs/RigidBodies/lowerleg_link_r_i>
            point3f physics:localPos0 = (0.0091059655, -0.002496653, -0.051889222)
            point3f physics:localPos1 = (-0.0021506585, 0.00002157416, 0.020890601)
            quatf physics:localRot0 = (0.58797973, 0.4910233, 0.41201746, 0.4933736)
            quatf physics:localRot1 = (0.58797973, 0.4910233, 0.41201746, 0.4933736)
        }

        def PhysicsRevoluteJoint "j4_r_i" (
            customData = {
                string uuid = "c9af911c-e52f-4e32-a2a8-f385e33373d6"
            }
        )
        {
            uniform token physics:axis = "X"
            rel physics:body0 = </DR_Legs/RigidBodies/lowerleg_link_r_i>
            rel physics:body1 = </DR_Legs/RigidBodies/ankle_bracket_a_r_i>
            point3f physics:localPos0 = (-0.016862756, 0.002615714, -0.0607539)
            point3f physics:localPos1 = (-0.000028822069, -0.0030451445, 0.0012155819)
            quatf physics:localRot0 = (0.055807292, 0.765188, -0.06694527, 0.63788027)
            quatf physics:localRot1 = (0.055807292, 0.765188, -0.06694527, 0.63788027)
        }

        def PhysicsRevoluteJoint "j5_r_i" (
            customData = {
                string uuid = "c8c44477-0077-4508-a69c-5c91951c0edf"
            }
        )
        {
            uniform token physics:axis = "X"
            rel physics:body0 = </DR_Legs/RigidBodies/ankle_bracket_a_r_i>
            rel physics:body1 = </DR_Legs/RigidBodies/ankle_bracket_b_r_i>
            point3f physics:localPos0 = (-0.0049919393, -0.002170013, -0.02632714)
            point3f physics:localPos1 = (0.0010595476, 0.0060089934, -5.228582e-9)
            quatf physics:localRot0 = (-0.002277571, 0.12503013, 0.6959651, 0.70710313)
            quatf physics:localRot1 = (-0.002277571, 0.12503013, 0.6959651, 0.70710313)
        }

        def PhysicsRevoluteJoint "j6_r_i" (
            prepend apiSchemas = ["PhysicsDriveAPI:angular"]
            customData = {
                string uuid = "55ce3f2e-052a-4ee8-ac85-3be98ed441cc"
            }
        )
        {
            float drive:angular:physics:maxForce = inf
            uniform token physics:axis = "X"
            rel physics:body0 = </DR_Legs/RigidBodies/foot_r>
            rel physics:body1 = </DR_Legs/RigidBodies/ankle_bracket_b_r_i>
            point3f physics:localPos0 = (-0.0026218148, 0.03236255, 0.0140596405)
            point3f physics:localPos1 = (0.0010595476, 0.0060089934, -5.228582e-9)
            quatf physics:localRot0 = (0.7629104, 0.069222845, 0.058084864, 0.6401578)
            quatf physics:localRot1 = (0.7629104, 0.069222845, 0.058084864, 0.6401578)
            float physics:lowerLimit = -inf
            float physics:upperLimit = inf
        }

        def PhysicsRevoluteJoint "j7_r_i" (
            prepend apiSchemas = ["PhysicsDriveAPI:angular"]
            customData = {
                string uuid = "81ccf9c1-8e88-44f9-afb2-d946c8489f82"
            }
        )
        {
            float drive:angular:physics:maxForce = inf
            uniform token physics:axis = "X"
            rel physics:body0 = </DR_Legs/RigidBodies/hip_servos_r_i>
            rel physics:body1 = </DR_Legs/RigidBodies/servohorn_r_i>
            point3f physics:localPos0 = (0.015924355, 0.015923342, 0.015332192)
            point3f physics:localPos1 = (-0.024587424, 0.002106128, -0.010306938)
            quatf physics:localRot0 = (-0.38962528, 0.6595576, 0.55343455, -0.32693443)
            quatf physics:localRot1 = (-0.38962528, 0.6595576, 0.55343455, -0.32693443)
            float physics:lowerLimit = -inf
            float physics:upperLimit = inf
        }

        def PhysicsRevoluteJoint "j8_r_i" (
            customData = {
                string uuid = "1cea2b69-1b60-4c1b-abe0-09a6aea9b4a8"
            }
        )
        {
            uniform token physics:axis = "X"
            rel physics:body0 = </DR_Legs/RigidBodies/servohorn_r_i>
            rel physics:body1 = </DR_Legs/RigidBodies/upperleg_rod_r_i>
            point3f physics:localPos0 = (0.017242543, -0.010270599, 0.007867939)
            point3f physics:localPos1 = (0.0032588597, -0.0004986371, 0.063249186)
            quatf physics:localRot0 = (-0.019939138, 0.7657849, 0.64256984, -0.016730923)
            quatf physics:localRot1 = (-0.019939138, 0.7657849, 0.64256984, -0.016730923)
        }

        def PhysicsRevoluteJoint "j9_r_i" (
            customData = {
                string uuid = "0adfccb4-48dc-46ae-af02-c265f7224495"
            }
        )
        {
            uniform token physics:axis = "X"
            rel physics:body0 = </DR_Legs/RigidBodies/upperleg_rod_r_i>
            rel physics:body1 = </DR_Legs/RigidBodies/lowerleg_link_r_i>
            point3f physics:localPos0 = (-0.0032328705, 0.0006460301, -0.063249186)
            point3f physics:localPos1 = (0.040375788, 0.0042765774, 0.049304985)
            quatf physics:localRot0 = (-0.64256984, 0.016730923, -0.019939138, 0.7657849)
            quatf physics:localRot1 = (-0.64256984, 0.016730923, -0.019939138, 0.7657849)
        }

        def PhysicsRevoluteJoint "j1_r_o" (
            customData = {
                string uuid = "5cd92e89-2f04-491d-9c0d-c41fb7e129f9"
            }
        )
        {
            uniform token physics:axis = "X"
            rel physics:body0 = </DR_Legs/RigidBodies/pelvis>
            rel physics:body1 = </DR_Legs/RigidBodies/hip_servos_r_o>
            point3f physics:localPos0 = (-0.0036229661, -0.0973522, -0.02857228)
            point3f physics:localPos1 = (-0.022200545, 0.0019708313, -0.0129316235)
            quatf physics:localRot0 = (1.009236e-16, 0.9961947, -0.087155744, 1.2027606e-16)
            quatf physics:localRot1 = (1.009236e-16, 0.9961947, -0.087155744, 1.2027606e-16)
        }

        def PhysicsRevoluteJoint "j2_r_o" (
            prepend apiSchemas = ["PhysicsDriveAPI:angular"]
            customData = {
                string uuid = "a4581328-8099-436e-8931-f6031fae9458"
            }
        )
        {
            float drive:angular:physics:maxForce = inf
            uniform token physics:axis = "X"
            rel physics:body0 = </DR_Legs/RigidBodies/hip_servos_r_o>
            rel physics:body1 = </DR_Legs/RigidBodies/upperleg_link_r_o>
            point3f physics:localPos0 = (-0.01349425, -0.016318863, -0.0129316235)
            point3f physics:localPos1 = (-0.0125058545, -0.013658319, 0.056396194)
            quatf physics:localRot0 = (-0.6403416, -0.056022633, 0.066765174, 0.7631294)
            quatf physics:localRot1 = (-0.6403416, -0.056022633, 0.066765174, 0.7631294)
            float physics:lowerLimit = -inf
            float physics:upperLimit = inf
        }

        def PhysicsRevoluteJoint "j3_r_o" (
            customData = {
                string uuid = "70e54c4f-b16c-4aeb-aae2-504e7a8741b4"
            }
        )
        {
            uniform token physics:axis = "X"
            rel physics:body0 = </DR_Legs/RigidBodies/upperleg_link_r_o>
            rel physics:body1 = </DR_Legs/RigidBodies/lowerleg_link_r_o>
            point3f physics:localPos0 = (0.009170448, -0.000725897, -0.05193266)
            point3f physics:localPos1 = (-0.0019356288, 0.0006986013, 0.020900147)
            quatf physics:localRot0 = (0.58682406, 0.49240386, 0.4131759, 0.49240386)
            quatf physics:localRot1 = (0.58682406, 0.49240386, 0.4131759, 0.49240386)
        }

        def PhysicsRevoluteJoint "j4_r_o" (
            customData = {
                string uuid = "2c159f4a-fcab-4820-a02b-95b1ebe3f4ff"
            }
        )
        {
            uniform token physics:axis = "X"
            rel physics:body0 = </DR_Legs/RigidBodies/lowerleg_link_r_o>
            rel physics:body1 = </DR_Legs/RigidBodies/ankle_bracket_a_r_o>
            point3f physics:localPos0 = (-0.017009294, 0.0033564952, -0.06067632)
            point3f physics:localPos1 = (0.00049046456, 0.0029637474, 0.0013141811)
            quatf physics:localRot0 = (-0.5027277, 0.58143795, 0.40240514, 0.49725735)
            quatf physics:localRot1 = (-0.5027277, 0.58143795, 0.40240514, 0.49725735)
        }

        def PhysicsRevoluteJoint "j5_r_o" (
            customData = {
                string uuid = "6c52c7f1-aa2c-4772-838f-67058339bba2"
            }
        )
        {
            uniform token physics:axis = "X"
            rel physics:body0 = </DR_Legs/RigidBodies/ankle_bracket_a_r_o>
            rel physics:body1 = </DR_Legs/RigidBodies/ankle_bracket_b_r_o>
            point3f physics:localPos0 = (-0.0045946273, 0.003860386, -0.026205592)
            point3f physics:localPos1 = (-0.0010595495, -0.0060089934, -4.9155724e-9)
            quatf physics:localRot0 = (0.9919141, 0.008070966, 0.09225156, -0.08678123)
            quatf physics:localRot1 = (0.9919141, 0.008070966, 0.09225156, -0.08678123)
        }

        def PhysicsRevoluteJoint "j6_r_o" (
            customData = {
                string uuid = "ce945b5e-6b51-4149-9ef9-18bb1ddfcc4b"
            }
        )
        {
            uniform token physics:axis = "X"
            rel physics:body0 = </DR_Legs/RigidBodies/ankle_bracket_b_r_o>
            rel physics:body1 = </DR_Legs/RigidBodies/foot_r>
            point3f physics:localPos0 = (-0.0010595495, -0.0060089934, -4.9155724e-9)
            point3f physics:localPos1 = (-0.013648474, -0.030172743, 0.0140596405)
            quatf physics:localRot0 = (0.48918638, 0.5895089, 0.4946567, 0.41047612)
            quatf physics:localRot1 = (0.48918638, 0.5895089, 0.4946567, 0.41047612)
        }

        def PhysicsRevoluteJoint "j7_r_o" (
            prepend apiSchemas = ["PhysicsDriveAPI:angular"]
            customData = {
                string uuid = "61dd8e2f-c07b-4538-8179-09299fca174a"
            }
        )
        {
            float drive:angular:physics:maxForce = inf
            uniform token physics:axis = "X"
            rel physics:body0 = </DR_Legs/RigidBodies/hip_servos_r_o>
            rel physics:body1 = </DR_Legs/RigidBodies/servohorn_r_o>
            point3f physics:localPos0 = (0.010141136, -0.020486418, 0.0155683765)
            point3f physics:localPos1 = (-0.023895144, 0.0064426707, -0.010134094)
            quatf physics:localRot0 = (-0.38575703, -0.5141667, 0.61276007, 0.45972732)
            quatf physics:localRot1 = (-0.38575703, -0.5141667, 0.61276007, 0.45972732)
            float physics:lowerLimit = -inf
            float physics:upperLimit = inf
        }

        def PhysicsRevoluteJoint "j8_r_o" (
            customData = {
                string uuid = "83b4f688-5cdb-4278-8397-c6ee725f9264"
            }
        )
        {
            uniform token physics:axis = "X"
            rel physics:body0 = </DR_Legs/RigidBodies/servohorn_r_o>
            rel physics:body1 = </DR_Legs/RigidBodies/upperleg_rod_r_o>
            point3f physics:localPos0 = (0.019795543, 0.0038921137, 0.007736945)
            point3f physics:localPos1 = (0.0035088737, -0.0005427213, 0.06323544)
            quatf physics:localRot0 = (-0.021476122, 0.7657433, 0.642535, -0.018020606)
            quatf physics:localRot1 = (-0.021476122, 0.7657433, 0.642535, -0.018020606)
        }

        def PhysicsRevoluteJoint "j9_r_o" (
            customData = {
                string uuid = "91895961-a3ae-4440-a8f6-29fb675bb7ad"
            }
        )
        {
            uniform token physics:axis = "X"
            rel physics:body0 = </DR_Legs/RigidBodies/upperleg_rod_r_o>
            rel physics:body1 = </DR_Legs/RigidBodies/lowerleg_link_r_o>
            point3f physics:localPos0 = (-0.0034828843, 0.0006901143, -0.06323544)
            point3f physics:localPos1 = (0.036722384, -0.0177191, 0.049129155)
            quatf physics:localRot0 = (-0.642535, 0.018020606, -0.021476122, 0.7657433)
            quatf physics:localRot1 = (-0.642535, 0.018020606, -0.021476122, 0.7657433)
        }
    }

    def Scope "Materials"
    {
    }

    def Scope "Collisions"
    {
        def PhysicsCollisionGroup "DefaultGroup"
        {
            prepend rel collection:colliders:includes = </DR_Legs>
        }
    }
}
